Workbook
Name appimg: INDEX([1]Utility!$P:$P,MATCH('[1]DCDC Ref'!$W$21,[1]Utility!$O:$O,0))
Name boardimg: INDEX([1]Utility!$X:$X,MATCH('[1]DCDC Ref'!$W$21,[1]Utility!$O:$O,0))
Name L1Round: TRUNC(ROUND('All Data'!XFD1,2),2)

Sheet All Data
AS1: 新 (全ての品番に共通するようになっていた)↓下記$AO$2で関数参照する。 | BZ1: Vin | CA1: ='[1]DCDC Ref'!J21 -> 12 | CC1: V
AS2: https://industrial.panasonic.com/ww/products/inductors/automotive-inductors/automotive-inductors/models/ | BZ2: Vout | CA2: ='[1]DCDC Ref'!J22 -> 5 | CC2: V
BC3: L範囲とI範囲で表示絞る …却下。L値が何も出ないと気付きが得られない。条件書式設定でNGを示す。 | BZ3: Mode | CA3: =IF(CA1=CA2,"",IF(CA1>CA2,"Buck","Boost")) -> Buck
BC4: =IF(Q11>='DCDC Ref'!$J$29*'DCDC Ref'!$J$30/100,0, IF(Q11<='DCDC Ref'!$J$29*'DCDC Ref'!$J$31/100,0, IF(X11<('DCDC Ref'!$J$24/'DCDC Ref'!$J$27)*'DCDC Ref'!$J$25/100,0,1))) | BZ4: Iout | CA4: ='[1]DCDC Ref'!J24 -> 10 | CC4: A
BC5: I範囲で表示絞る …適用中。多少Lずれてもいいが、電流値は必須要件。 | BZ5: Fsw | CA5: ='[1]DCDC Ref'!J25 -> 2000 | CC5: kHz
BC6: =IF(X11<('DCDC Ref'!$J$24/'DCDC Ref'!$J$27)*'DCDC Ref'!$J$25/100,0,1) | BO6: L Weight | BP6: 5000 | BZ6: Phase | CA6: ='[1]DCDC Ref'!J26 -> 1 | CC6: ph
BD7: o | BG7: x | BJ7: o | BO7: I1,I2 Weight | BP7: 5 | BZ7: Ripple | CA7: ='[1]DCDC Ref'!J27 -> 30 | CC7: %
B8: 上記からcsvでWeb公開品(カタログ品)の品番リストをDLし、Part Number列の最下に貼り付け氏、重複条件付き書式でカタログ品のみへフィルタリングした。 | U8: DCR | X8: I (⊿T) | Y8: I (⊿T) | Z8: Isat ⊿L=-30% | AA8: Isat ⊿L=-20% | AB8: Max Operating Voltage (V) | AG8: Dimmension (mm) | AM8: Vibration | AO8: L1(at Ir) *Consumer product only | BC8: ※Isat(-30%)選択中 | BD8: L | BG8: I1 | BJ8: I2 | BZ8: L | CA8: ='[1]DCDC Ref'!J30 -> 0.63194444 | CC8: uH
B9: ↓ | O9: Part Number | Q9: L(uH) | T9: % | U9: typ(mΩ) | V9: max(mΩ) | W9: Tol. (%) | X9: method B | Y9: method A | Z9: typ(A) | AA9: typ(A) | AO9: L(uH) | AQ9: % | AR9: at Ir | BC9: ↓ | BD9: L値 | BG9: I rated値 (Method B) | BJ9: Isat値 (-30%)
A10: Original Order | B10: カタログ品 | C10: 確認メモ | D10: Check | E10: Renewal Date | F10: Status | G10: Maker | H10: Type | I10: Core | J10: Category | K10: Feature | L10: Series | M10: Series (Size) | N10: Automotive Grade | O10: Part Number | P10: 仮1 | Q10: Lo (uH) | R10: Lo RangeXX | S10: Lo Range (uH) | T10: Lo Tol. (%) | U10: DCR Typ (mOhm) | V10: DCR Max (mOhm) | W10: DCR Tol. (%) | X10: Method B (A typ at 40℃) | Y10: Method A (A typ at 40℃) | Z10: ⊿L=-30% typ (A) | AA10: ⊿L=-20% typ (A) | AB10: L (mm) | AC10: W (mm) | AD10: Max Height (mm) | AE10: Area (mm2) | AF10: Size (mm) | AG10: Rough Size (mm) | AH10: Max Height Range (mm) | AI10: Min Temp (deg.C) | AJ10: Max Temp (deg.C) | AK10: Temp Range (deg.C) | AL10: Max Voltage (V) | AM10: Vibration | AN10: MPQ | AO10: L1 (uH) | AP10: Rough L1 (uH) | AQ10: L1 Tol. (%) | AR10: Ir (A) | AS10: URL | AT10: Image URL | AU10: add3 | AV10: add4 | AW10: add5 | BC10: 該非判定 | BD10: %_Diff_L | BE10: ABS | BG10: %_Diff_I | BH10: NegaDown | BJ10: %_Diff_I | BK10: NegaDown | BQ10: L+I Weighted | BR10: 小差順位(同一値も連番) | BS10: 除外後順位 | BT10: 一致一覧 | BU10: 提案表示
A11: 37 | B11: 〇 | D11: OK | F11: MP | G11: Panasonic | H11: SMD | I11: Metal Composite | J11: PCC | K11: High Isat (Standard) | L11: 5M-YLC | M11: PCC-M1050ML | N11: Yes | O11: ETQP5MR33YLC | P11: =MID(All_PCC_a[[#This Row],[Part Number]],7,3) -> R33 | Q11: 0.33 | R11: =IF(All_PCC_a[[#This Row],[Lo (uH)]]<1,"<1",IF(All_PCC_a[[#This Row],[Lo (uH)]]<10,"<10",IF(All_PCC_a[[#This Row],[Lo (uH)]]<100,"<100",IF(All_PCC_a[[#This Row],[Lo (uH)]]<2000,"<2000","")))) -> <1 | S11: =IFERROR(VLOOKUP(All_PCC_a[[#This Row],[Lo (uH)]],[1]Utility!$D$5:$E$43,2,1),"-") -> ≤ 0.4 | T11: 0.2 | U11: 1.1 | V11: 1.21 | W11: 10 | X11: 39.7 | Y11: 33.2 | Z11: 56.7 | AA11: 42.63 | AB11: 10.9 | AC11: 10 | AD11: 5 | AE11: =ROUND(All_PCC_a[[#This Row],[L (mm)]]*All_PCC_a[[#This Row],[W (mm)]],1) -> 109 | AF11: =All_PCC_a[[#This Row],[L (mm)]]&" x "&All_PCC_a[[#This Row],[W (mm)]] -> 10,9 x 10 | AG11: 10 x 10 | AH11: =IF(All_PCC_a[[#This Row],[Max Height (mm)]]<=9,"≤ "&ROUNDUP(AD11,0),"≤"&ROUNDUP(AD11,0)) -> ≤ 5 | AI11: -40 | AJ11: 150 | AK11: =All_PCC_a[[#This Row],[Min Temp (deg.C)]]&" to +"&All_PCC_a[[#This Row],[Max Temp (deg.C)]] -> -40 to +150 | AO11: - | AP11: =IFERROR(IF(L1Round>1,ROUND(L1Round,1),L1Round),"-") -> - | AQ11: - | AR11: - | AS11: https://industrial.panasonic.com/ww/products/pt/automotive-inductors/models/ETQP5MR33YLC | AT11: https://industrial.panasonic.com/content/data/CC/pictures/lineup-Metal-core.gif | AU11: =_xlfn.IMAGE(All_PCC_a[[#This Row],[Image URL]]) -> #NAME? | AZ11: =IF(AY11=1,COUNTIF($AY$11:AY11,1),"") | BC11: =IF(Z11<('[1]DCDC Ref'!$J$24/'[1]DCDC Ref'!$J$26)*'[1]DCDC Ref'!$J$28/100,0,1) -> 1 | BD11: =IF(BC11=1000000000,"",('All Data'!Q11-'[1]DCDC Ref'!$J$30)/'[1]DCDC Ref'!$J$30*100) -> -47.78022 | BE11: =ABS(BD11) -> 47.78022 | BH11: =IF(BG11<0,10000,BG11) -> 0 | BJ11: =IF(BC11=0,"",('All Data'!Z11-'[1]DCDC Ref'!$J$28*('[1]DCDC Ref'!$J$29/100))/'[1]DCDC Ref'!$J$28*('[1]DCDC Ref'!$J$29/100)*100) -> 408.34483 | BK11: =IF(BJ11<0,10000,BJ11) -> 408.34483 | BQ11: =IFERROR(BE11*$BP$6+BK11*$BP$7,"") -> 240942.82 | BR11: =IF(BQ11="","",RANK(BQ11,BQ$11:BQ$9930,1)+COUNTIF(BQ$11:BQ11,BQ11)-1) -> 16 | BS11: =RANK(BR11,BR$11:BR$9930,1) -> 16 | BT11: =IFERROR(INDEX($O$11:$O$1013,MATCH(ROWS($BS$11:BS11),$BS$11:$BS$1005,0)),"") -> ETQP3MR68KVP | BU11: =IF(BT11<>"",BT11,"") -> ETQP3MR68KVP
A12: 45 | B12: 〇 | C12: 2023/3/10MP, 2022/5/27 UD扱いへ(誤記だったとのこと)。2022/1/12 MPカタログ扱いへ。2021/11/12カタログUD 扱い。2021/3/23追加。 | D12: OK | F12: MP | G12: Panasonic | H12: SMD | I12: Metal Composite | J12: PCC | K12: High Current (≥□12) | L12: 8M-JFA | M12: PCC-M1280MF | N12: Yes | O12: ETQP8MR33JFA | P12: =MID(All_PCC_a[[#This Row],[Part Number]],7,3) -> R33 | Q12: 0.33 | R12: =IF(All_PCC_a[[#This Row],[Lo (uH)]]<1,"<1",IF(All_PCC_a[[#This Row],[Lo (uH)]]<10,"<10",IF(All_PCC_a[[#This Row],[Lo (uH)]]<100,"<100",IF(All_PCC_a[[#This Row],[Lo (uH)]]<2000,"<2000","")))) -> <1 | S12: =IFERROR(VLOOKUP(All_PCC_a[[#This Row],[Lo (uH)]],[1]Utility!$D$5:$E$43,2,1),"-") -> ≤ 0.4 | T12: 0.2 | U12: 0.7 | V12: 0.77 | W12: 10 | X12: 53.5 | Y12: 44.4 | Z12: 84.5 | AA12: =ROUND(55.8461538461538,2) -> 55.85 | AB12: 12.6 | AC12: 13.2 | AD12: 8 | AE12: =ROUND(All_PCC_a[[#This Row],[L (mm)]]*All_PCC_a[[#This Row],[W (mm)]],1) -> 166.3 | AF12: =All_PCC_a[[#This Row],[L (mm)]]&" x "&All_PCC_a[[#This Row],[W (mm)]] -> 12,6 x 13,2 | AG12: 12 x 12 | AH12: =IF(All_PCC_a[[#This Row],[Max Height (mm)]]<=9,"≤ "&ROUNDUP(AD12,0),"≤"&ROUNDUP(AD12,0)) -> ≤ 8 | AI12: -40 | AJ12: 160 | AK12: =All_PCC_a[[#This Row],[Min Temp (deg.C)]]&" to +"&All_PCC_a[[#This Row],[Max Temp (deg.C)]] -> -40 to +160 | AN12: 15Gと聞いたがカタログは30G | AO12: - | AP12: =IFERROR(IF(L1Round>1,ROUND(L1Round,1),L1Round),"-") -> - | AQ12: - | AR12: - | AS12: https://industrial.panasonic.com/ww/products/pt/automotive-inductors/models/ETQP8MR33JFA | AT12: https://industrial.panasonic.com/content/data/CC/pictures/lineup-Large%20current.gif | AU12: =_xlfn.IMAGE(All_PCC_a[[#This Row],[Image URL]]) -> #NAME? | AZ12: =IF(AY12=1,COUNTIF($AY$11:AY12,1),"") | BC12: =IF(Z12<('[1]DCDC Ref'!$J$24/'[1]DCDC Ref'!$J$26)*'[1]DCDC Ref'!$J$28/100,0,1) -> 1 | BD12: =IF(BC12=1000000000,"",('All Data'!Q12-'[1]DCDC Ref'!$J$30)/'[1]DCDC Ref'!$J$30*100) -> -47.78022 | BE12: =ABS(BD12) -> 47.78022 | BH12: =IF(BG12<0,10000,BG12) -> 0 | BJ12: =IF(BC12=0,"",('All Data'!Z12-'[1]DCDC Ref'!$J$28*('[1]DCDC Ref'!$J$29/100))/'[1]DCDC Ref'!$J$28*('[1]DCDC Ref'!$J$29/100)*100) -> 657.58621 | BK12: =IF(BJ12<0,10000,BJ12) -> 657.58621 | BQ12: =IFERROR(BE12*$BP$6+BK12*$BP$7,"") -> 242189.03 | BR12: =IF(BQ12="","",RANK(BQ12,BQ$11:BQ$9930,1)+COUNTIF(BQ$11:BQ12,BQ12)-1) -> 17 | BS12: =RANK(BR12,BR$11:BR$9930,1) -> 17 | BT12: =IFERROR(INDEX($O$11:$O$1013,MATCH(ROWS($BS$11:BS12),$BS$11:$BS$1005,0)),"") -> ETQP3MR68KVN | BU12: =IF(BT12<>"",BT12,"") -> ETQP3MR68KVN
A13: 106 | B13: 〇 | D13: OK | F13: MP | G13: Panasonic | H13: SMD | I13: Metal Composite | J13: PCC | K13: LP (Low Profile) | L13: 3M-KVP | M13: PCC-M0530M-LP | N13: Yes | O13: ETQP3MR33KVP | P13: =MID(All_PCC_a[[#This Row],[Part Number]],7,3) -> R33 | Q13: 0.33 | R13: =IF(All_PCC_a[[#This Row],[Lo (uH)]]<1,"<1",IF(All_PCC_a[[#This Row],[Lo (uH)]]<10,"<10",IF(All_PCC_a[[#This Row],[Lo (uH)]]<100,"<100",IF(All_PCC_a[[#This Row],[Lo (uH)]]<2000,"<2000","")))) -> <1 | S13: =IFERROR(VLOOKUP(All_PCC_a[[#This Row],[Lo (uH)]],[1]Utility!$D$5:$E$43,2,1),"-") -> ≤ 0.4 | T13: 0.2 | U13: 4.85 | V13: 5.34 | W13: 10 | X13: 12.7 | Y13: 10.6 | Z13: 21.8 | AA13: 14.5 | AB13: 5.5 | AC13: 5 | AD13: 3 | AE13: =ROUND(All_PCC_a[[#This Row],[L (mm)]]*All_PCC_a[[#This Row],[W (mm)]],1) -> 27.5 | AF13: =All_PCC_a[[#This Row],[L (mm)]]&" x "&All_PCC_a[[#This Row],[W (mm)]] -> 5,5 x 5 | AG13: _5 x 5 | AH13: =IF(All_PCC_a[[#This Row],[Max Height (mm)]]<=9,"≤ "&ROUNDUP(AD13,0),"≤"&ROUNDUP(AD13,0)) -> ≤ 3 | AI13: -55 | AJ13: 155 | AK13: =All_PCC_a[[#This Row],[Min Temp (deg.C)]]&" to +"&All_PCC_a[[#This Row],[Max Temp (deg.C)]] -> -55 to +155 | AO13: - | AP13: =IFERROR(IF(L1Round>1,ROUND(L1Round,1),L1Round),"-") -> - | AQ13: - | AR13: - | AS13: https://industrial.panasonic.com/ww/products/pt/automotive-inductors/models/ETQP3MR33KVP | AT13: https://industrial.panasonic.com/content/data/CC/pictures/lineup-LP.gif | AU13: =_xlfn.IMAGE(All_PCC_a[[#This Row],[Image URL]]) -> #NAME? | BC13: =IF(Z13<('[1]DCDC Ref'!$J$24/'[1]DCDC Ref'!$J$26)*'[1]DCDC Ref'!$J$28/100,0,1) -> 1 | BD13: =IF(BC13=1000000000,"",('All Data'!Q13-'[1]DCDC Ref'!$J$30)/'[1]DCDC Ref'!$J$30*100) -> -47.78022 | BE13: =ABS(BD13) -> 47.78022 | BH13: =IF(BG13<0,10000,BG13) -> 0 | BJ13: =IF(BC13=0,"",('All Data'!Z13-'[1]DCDC Ref'!$J$28*('[1]DCDC Ref'!$J$29/100))/'[1]DCDC Ref'!$J$28*('[1]DCDC Ref'!$J$29/100)*100) -> 95.448276 | BK13: =IF(BJ13<0,10000,BJ13) -> 95.448276 | BQ13: =IFERROR(BE13*$BP$6+BK13*$BP$7,"") -> 239378.34 | BR13: =IF(BQ13="","",RANK(BQ13,BQ$11:BQ$9930,1)+COUNTIF(BQ$11:BQ13,BQ13)-1) -> 14 | BS13: =RANK(BR13,BR$11:BR$9930,1) -> 14 | BT13: =IFERROR(INDEX($O$11:$O$1013,MATCH(ROWS($BS$11:BS13),$BS$11:$BS$1005,0)),"") -> ETQP3MR68YFN | BU13: =IF(BT13<>"",BT13,"") -> ETQP3MR68YFN
A14: 116 | B14: 〇 | C14: 44677 | D14: OK | F14: MP | G14: Panasonic | H14: SMD | I14: Metal Composite | J14: PCC | K14: LP (Low Profile) | L14: 3M-KVP | M14: PCC-M0530M-LP | N14: Yes | O14: ETQP3MR47KVP | P14: =MID(All_PCC_a[[#This Row],[Part Number]],7,3) -> R47 | Q14: 0.47 | R14: =IF(All_PCC_a[[#This Row],[Lo (uH)]]<1,"<1",IF(All_PCC_a[[#This Row],[Lo (uH)]]<10,"<10",IF(All_PCC_a[[#This Row],[Lo (uH)]]<100,"<100",IF(All_PCC_a[[#This Row],[Lo (uH)]]<2000,"<2000","")))) -> <1 | S14: =IFERROR(VLOOKUP(All_PCC_a[[#This Row],[Lo (uH)]],[1]Utility!$D$5:$E$43,2,1),"-") -> ≤ 0.5 | T14: 0.2 | U14: 5.8 | V14: 6.38 | W14: 10 | X14: 11.6 | Y14: 9.6 | Z14: 17.9 | AA14: 12.9 | AB14: 5.5 | AC14: 5 | AD14: 3 | AE14: =ROUND(All_PCC_a[[#This Row],[L (mm)]]*All_PCC_a[[#This Row],[W (mm)]],1) -> 27.5 | AF14: =All_PCC_a[[#This Row],[L (mm)]]&" x "&All_PCC_a[[#This Row],[W (mm)]] -> 5,5 x 5 | AG14: _5 x 5 | AH14: =IF(All_PCC_a[[#This Row],[Max Height (mm)]]<=9,"≤ "&ROUNDUP(AD14,0),"≤"&ROUNDUP(AD14,0)) -> ≤ 3 | AI14: -55 | AJ14: 155 | AK14: =All_PCC_a[[#This Row],[Min Temp (deg.C)]]&" to +"&All_PCC_a[[#This Row],[Max Temp (deg.C)]] -> -55 to +155 | AO14: - | AP14: - | AQ14: - | AR14: - | AS14: https://industrial.panasonic.com/ww/products/pt/automotive-inductors/models/ETQP3MR47KVP | AT14: https://industrial.panasonic.com/content/data/CC/pictures/lineup-LP.gif | AU14: =_xlfn.IMAGE(All_PCC_a[[#This Row],[Image URL]]) -> #NAME? | AZ14: =IF(AY14=1,COUNTIF($AY$11:AY14,1),"") | BC14: =IF(Z14<('[1]DCDC Ref'!$J$24/'[1]DCDC Ref'!$J$26)*'[1]DCDC Ref'!$J$28/100,0,1) -> 1 | BD14: =IF(BC14=1000000000,"",('All Data'!Q14-'[1]DCDC Ref'!$J$30)/'[1]DCDC Ref'!$J$30*100) -> -25.626374 | BE14: =ABS(BD14) -> 25.626374 | BH14: =IF(BG14<0,10000,BG14) -> 0 | BJ14: =IF(BC14=0,"",('All Data'!Z14-'[1]DCDC Ref'!$J$28*('[1]DCDC Ref'!$J$29/100))/'[1]DCDC Ref'!$J$28*('[1]DCDC Ref'!$J$29/100)*100) -> 60.482759 | BK14: =IF(BJ14<0,10000,BJ14) -> 60.482759 | BQ14: =IFERROR(BE14*$BP$6+BK14*$BP$7,"") -> 128434.28 | BR14: =IF(BQ14="","",RANK(BQ14,BQ$11:BQ$9930,1)+COUNTIF(BQ$11:BQ14,BQ14)-1) -> 9 | BS14: =RANK(BR14,BR$11:BR$9930,1) -> 9 | BT14: =IFERROR(INDEX($O$11:$O$1013,MATCH(ROWS($BS$11:BS14),$BS$11:$BS$1005,0)),"") -> ETQP4MR68KVK | BU14: =IF(BT14<>"",BT14,"") -> ETQP4MR68KVK
A15: 119 | B15: 〇 | C15: 2022/6/30カタログ追加 | D15: OK | F15: MP | G15: Panasonic | H15: SMD | I15: Metal Composite | J15: PCC | K15: High Isat (Standard) | L15: 4M-KLC | M15: PCC-M1040ML | N15: Yes | O15: ETQP4MR47KLC | P15: =MID(All_PCC_a[[#This Row],[Part Number]],7,3) -> R47 | Q15: 0.47 | R15: =IF(All_PCC_a[[#This Row],[Lo (uH)]]<1,"<1",IF(All_PCC_a[[#This Row],[Lo (uH)]]<10,"<10",IF(All_PCC_a[[#This Row],[Lo (uH)]]<100,"<100",IF(All_PCC_a[[#This Row],[Lo (uH)]]<2000,"<2000","")))) -> <1 | S15: =IFERROR(VLOOKUP(All_PCC_a[[#This Row],[Lo (uH)]],[1]Utility!$D$5:$E$43,2,1),"-") -> ≤ 0.5 | T15: 0.2 | U15: 1.53 | V15: 1.68 | W15: 10 | X15: 31.1 | Y15: 24.9 | Z15: 47.3 | AA15: 33.2 | AB15: 10.9 | AC15: 10 | AD15: 4 | AE15: =ROUND(All_PCC_a[[#This Row],[L (mm)]]*All_PCC_a[[#This Row],[W (mm)]],1) -> 109 | AF15: =All_PCC_a[[#This Row],[L (mm)]]&" x "&All_PCC_a[[#This Row],[W (mm)]] -> 10,9 x 10 | AG15: 10 x 10 | AH15: =IF(All_PCC_a[[#This Row],[Max Height (mm)]]<=9,"≤ "&ROUNDUP(AD15,0),"≤"&ROUNDUP(AD15,0)) -> ≤ 4 | AI15: -40 | AJ15: 150 | AK15: =All_PCC_a[[#This Row],[Min Temp (deg.C)]]&" to +"&All_PCC_a[[#This Row],[Max Temp (deg.C)]] -> -40 to +150 | AO15: - | AP15: =IFERROR(IF(L1Round>1,ROUND(L1Round,1),L1Round),"-") -> - | AQ15: - | AR15: - | AS15: https://industrial.panasonic.com/ww/products/pt/automotive-inductors/models/ETQP4MR47KLC | AT15: https://industrial.panasonic.com/content/data/CC/pictures/lineup-Metal-core.gif | AU15: =_xlfn.IMAGE(All_PCC_a[[#This Row],[Image URL]]) -> #NAME? | AZ15: =IF(AY15=1,COUNTIF($AY$11:AY15,1),"") | BC15: =IF(Z15<('[1]DCDC Ref'!$J$24/'[1]DCDC Ref'!$J$26)*'[1]DCDC Ref'!$J$28/100,0,1) -> 1 | BD15: =IF(BC15=1000000000,"",('All Data'!Q15-'[1]DCDC Ref'!$J$30)/'[1]DCDC Ref'!$J$30*100) -> -25.626374 | BE15: =ABS(BD15) -> 25.626374 | BH15: =IF(BG15<0,10000,BG15) -> 0 | BJ15: =IF(BC15=0,"",('All Data'!Z15-'[1]DCDC Ref'!$J$28*('[1]DCDC Ref'!$J$29/100))/'[1]DCDC Ref'!$J$28*('[1]DCDC Ref'!$J$29/100)*100) -> 324.06897 | BK15: =IF(BJ15<0,10000,BJ15) -> 324.06897 | BQ15: =IFERROR(BE15*$BP$6+BK15*$BP$7,"") -> 129752.21 | BR15: =IF(BQ15="","",RANK(BQ15,BQ$11:BQ$9930,1)+COUNTIF(BQ$11:BQ15,BQ15)-1) -> 13 | BS15: =RANK(BR15,BR$11:BR$9930,1) -> 13 | BT15: =IFERROR(INDEX($O$11:$O$1013,MATCH(ROWS($BS$11:BS15),$BS$11:$BS$1005,0)),"") -> ETQP5MR68YLC | BU15: =IF(BT15<>"",BT15,"") -> ETQP5MR68YLC
A16: 1 | B16: 〇 | D16: OK | F16: MP | G16: Panasonic | H16: SMD | I16: Metal Composite | J16: PCC | K16: High Isat (Standard) | L16: 3M-YFN | M16: PCC-M0630M | N16: Yes | O16: ETQP3MR68YFN | P16: =MID(All_PCC_a[[#This Row],[Part Number]],7,3) -> R68 | Q16: 0.68 | R16: =IF(All_PCC_a[[#This Row],[Lo (uH)]]<1,"<1",IF(All_PCC_a[[#This Row],[Lo (uH)]]<10,"<10",IF(All_PCC_a[[#This Row],[Lo (uH)]]<100,"<100",IF(All_PCC_a[[#This Row],[Lo (uH)]]<2000,"<2000","")))) -> <1 | S16: =IFERROR(VLOOKUP(All_PCC_a[[#This Row],[Lo (uH)]],[1]Utility!$D$5:$E$43,2,1),"-") -> ≤ 0.7 | T16: 0.2 | U16: 6.3 | V16: 6.93 | W16: 10 | X16: 12 | Y16: 9.8 | Z16: 24 | AA16: 17.66 | AB16: 6.5 | AC16: 6 | AD16: 3 | AE16: =ROUND(All_PCC_a[[#This Row],[L (mm)]]*All_PCC_a[[#This Row],[W (mm)]],1) -> 39 | AF16: =All_PCC_a[[#This Row],[L (mm)]]&" x "&All_PCC_a[[#This Row],[W (mm)]] -> 6,5 x 6 | AG16: _6 x 6 | AH16: =IF(All_PCC_a[[#This Row],[Max Height (mm)]]<=9,"≤ "&ROUNDUP(AD16,0),"≤"&ROUNDUP(AD16,0)) -> ≤ 3 | AI16: -40 | AJ16: 150 | AK16: =All_PCC_a[[#This Row],[Min Temp (deg.C)]]&" to +"&All_PCC_a[[#This Row],[Max Temp (deg.C)]] -> -40 to +150 | AO16: - | AP16: =IFERROR(IF(L1Round>1,ROUND(L1Round,1),L1Round),"-") -> - | AQ16: - | AR16: - | AS16: https://industrial.panasonic.com/ww/products/pt/automotive-inductors/models/ETQP3MR68YFN | AT16: https://industrial.panasonic.com/content/data/CC/pictures/lineup-Metal-core.gif | AU16: =_xlfn.IMAGE(All_PCC_a[[#This Row],[Image URL]]) -> #NAME? | BC16: =IF(Z16<('[1]DCDC Ref'!$J$24/'[1]DCDC Ref'!$J$26)*'[1]DCDC Ref'!$J$28/100,0,1) -> 1 | BD16: =IF(BC16=1000000000,"",('All Data'!Q16-'[1]DCDC Ref'!$J$30)/'[1]DCDC Ref'!$J$30*100) -> 7.6043956 | BE16: =ABS(BD16) -> 7.6043956 | BH16: =IF(BG16<0,10000,BG16) -> 0 | BJ16: =IF(BC16=0,"",('All Data'!Z16-'[1]DCDC Ref'!$J$28*('[1]DCDC Ref'!$J$29/100))/'[1]DCDC Ref'!$J$28*('[1]DCDC Ref'!$J$29/100)*100) -> 115.17241 | BK16: =IF(BJ16<0,10000,BJ16) -> 115.17241 | BQ16: =IFERROR(BE16*$BP$6+BK16*$BP$7,"") -> 38597.84 | BR16: =IF(BQ16="","",RANK(BQ16,BQ$11:BQ$9930,1)+COUNTIF(BQ$11:BQ16,BQ16)-1) -> 3 | BS16: =RANK(BR16,BR$11:BR$9930,1) -> 3 | BT16: =IFERROR(INDEX($O$11:$O$1013,MATCH(ROWS($BS$11:BS16),$BS$11:$BS$1005,0)),"") -> ETQP5MR68YSC | BU16: =IF(BT16<>"",BT16,"") -> ETQP5MR68YSC
A17: 38 | B17: 〇 | D17: OK | F17: MP | G17: Panasonic | H17: SMD | I17: Metal Composite | J17: PCC | K17: High Isat (Standard) | L17: 5M-YLC | M17: PCC-M1050ML | N17: Yes | O17: ETQP5MR68YLC | P17: =MID(All_PCC_a[[#This Row],[Part Number]],7,3) -> R68 | Q17: 0.68 | R17: =IF(All_PCC_a[[#This Row],[Lo (uH)]]<1,"<1",IF(All_PCC_a[[#This Row],[Lo (uH)]]<10,"<10",IF(All_PCC_a[[#This Row],[Lo (uH)]]<100,"<100",IF(All_PCC_a[[#This Row],[Lo (uH)]]<2000,"<2000","")))) -> <1 | S17: =IFERROR(VLOOKUP(All_PCC_a[[#This Row],[Lo (uH)]],[1]Utility!$D$5:$E$43,2,1),"-") -> ≤ 0.7 | T17: 0.2 | U17: 1.75 | V17: 1.93 | W17: 10 | X17: 31.5 | Y17: 26.3 | Z17: 40 | AA17: 28.37 | AB17: 10.9 | AC17: 10 | AD17: 5 | AE17: =ROUND(All_PCC_a[[#This Row],[L (mm)]]*All_PCC_a[[#This Row],[W (mm)]],1) -> 109 | AF17: =All_PCC_a[[#This Row],[L (mm)]]&" x "&All_PCC_a[[#This Row],[W (mm)]] -> 10,9 x 10 | AG17: 10 x 10 | AH17: =IF(All_PCC_a[[#This Row],[Max Height (mm)]]<=9,"≤ "&ROUNDUP(AD17,0),"≤"&ROUNDUP(AD17,0)) -> ≤ 5 | AI17: -40 | AJ17: 150 | AK17: =All_PCC_a[[#This Row],[Min Temp (deg.C)]]&" to +"&All_PCC_a[[#This Row],[Max Temp (deg.C)]] -> -40 to +150 | AO17: - | AP17: =IFERROR(IF(L1Round>1,ROUND(L1Round,1),L1Round),"-") -> - | AQ17: - | AR17: - | AS17: https://industrial.panasonic.com/ww/products/pt/automotive-inductors/models/ETQP5MR68YLC | AT17: https://industrial.panasonic.com/content/data/CC/pictures/lineup-Metal-core.gif | AU17: =_xlfn.IMAGE(All_PCC_a[[#This Row],[Image URL]]) -> #NAME? | BC17: =IF(Z17<('[1]DCDC Ref'!$J$24/'[1]DCDC Ref'!$J$26)*'[1]DCDC Ref'!$J$28/100,0,1) -> 1 | BD17: =IF(BC17=1000000000,"",('All Data'!Q17-'[1]DCDC Ref'!$J$30)/'[1]DCDC Ref'!$J$30*100) -> 7.6043956 | BE17: =ABS(BD17) -> 7.6043956 | BH17: =IF(BG17<0,10000,BG17) -> 0 | BJ17: =IF(BC17=0,"",('All Data'!Z17-'[1]DCDC Ref'!$J$28*('[1]DCDC Ref'!$J$29/100))/'[1]DCDC Ref'!$J$28*('[1]DCDC Ref'!$J$29/100)*100) -> 258.62069 | BK17: =IF(BJ17<0,10000,BJ17) -> 258.62069 | BQ17: =IFERROR(BE17*$BP$6+BK17*$BP$7,"") -> 39315.081 | BR17: =IF(BQ17="","",RANK(BQ17,BQ$11:BQ$9930,1)+COUNTIF(BQ$11:BQ17,BQ17)-1) -> 5 | BS17: =RANK(BR17,BR$11:BR$9930,1) -> 5 | BT17: =IFERROR(INDEX($O$11:$O$1013,MATCH(ROWS($BS$11:BS17),$BS$11:$BS$1005,0)),"") -> ETQP8MR68JFA | BU17: =IF(BT17<>"",BT17,"") -> ETQP8MR68JFA
A18: 46 | B18: 〇 | D18: OK | F18: MP | G18: Panasonic | H18: SMD | I18: Metal Composite | J18: PCC | K18: High Current (≥□12) | L18: 8M-JFA | M18: PCC-M1280MF | N18: Yes | O18: ETQP8MR68JFA | P18: =MID(All_PCC_a[[#This Row],[Part Number]],7,3) -> R68 | Q18: 0.68 | R18: =IF(All_PCC_a[[#This Row],[Lo (uH)]]<1,"<1",IF(All_PCC_a[[#This Row],[Lo (uH)]]<10,"<10",IF(All_PCC_a[[#This Row],[Lo (uH)]]<100,"<100",IF(All_PCC_a[[#This Row],[Lo (uH)]]<2000,"<2000","")))) -> <1 | S18: =IFERROR(VLOOKUP(All_PCC_a[[#This Row],[Lo (uH)]],[1]Utility!$D$5:$E$43,2,1),"-") -> ≤ 0.7 | T18: 0.2 | U18: 1.1 | V18: 1.21 | W18: 10 | X18: 42.6 | Y18: 35.4 | Z18: 56.9 | AA18: =ROUND(40.3333333333333,2) -> 40.33 | AB18: 12.6 | AC18: 13.2 | AD18: 8 | AE18: =ROUND(All_PCC_a[[#This Row],[L (mm)]]*All_PCC_a[[#This Row],[W (mm)]],1) -> 166.3 | AF18: =All_PCC_a[[#This Row],[L (mm)]]&" x "&All_PCC_a[[#This Row],[W (mm)]] -> 12,6 x 13,2 | AG18: 12 x 12 | AH18: =IF(All_PCC_a[[#This Row],[Max Height (mm)]]<=9,"≤ "&ROUNDUP(AD18,0),"≤"&ROUNDUP(AD18,0)) -> ≤ 8 | AI18: -40 | AJ18: 160 | AK18: =All_PCC_a[[#This Row],[Min Temp (deg.C)]]&" to +"&All_PCC_a[[#This Row],[Max Temp (deg.C)]] -> -40 to +160 | AN18: 15Gと聞いたがカタログは30G | AO18: - | AP18: =IFERROR(IF(L1Round>1,ROUND(L1Round,1),L1Round),"-") -> - | AQ18: - | AR18: - | AS18: https://industrial.panasonic.com/ww/products/pt/automotive-inductors/models/ETQP8MR68JFA | AT18: https://industrial.panasonic.com/content/data/CC/pictures/lineup-Large%20current.gif | AU18: =_xlfn.IMAGE(All_PCC_a[[#This Row],[Image URL]]) -> #NAME? | AZ18: =IF(AY18=1,COUNTIF($AY$11:AY18,1),"") | BC18: =IF(Z18<('[1]DCDC Ref'!$J$24/'[1]DCDC Ref'!$J$26)*'[1]DCDC Ref'!$J$28/100,0,1) -> 1 | BD18: =IF(BC18=1000000000,"",('All Data'!Q18-'[1]DCDC Ref'!$J$30)/'[1]DCDC Ref'!$J$30*100) -> 7.6043956 | BE18: =ABS(BD18) -> 7.6043956 | BH18: =IF(BG18<0,10000,BG18) -> 0 | BJ18: =IF(BC18=0,"",('All Data'!Z18-'[1]DCDC Ref'!$J$28*('[1]DCDC Ref'!$J$29/100))/'[1]DCDC Ref'!$J$28*('[1]DCDC Ref'!$J$29/100)*100) -> 410.13793 | BK18: =IF(BJ18<0,10000,BJ18) -> 410.13793 | BQ18: =IFERROR(BE18*$BP$6+BK18*$BP$7,"") -> 40072.668 | BR18: =IF(BQ18="","",RANK(BQ18,BQ$11:BQ$9930,1)+COUNTIF(BQ$11:BQ18,BQ18)-1) -> 7 | BS18: =RANK(BR18,BR$11:BR$9930,1) -> 7 | BT18: =IFERROR(INDEX($O$11:$O$1013,MATCH(ROWS($BS$11:BS18),$BS$11:$BS$1005,0)),"") -> ETQPAMR68JFW | BU18: =IF(BT18<>"",BT18,"") -> ETQPAMR68JFW
A19: 59 | B19: 〇 | D19: OK | F19: MP | G19: Panasonic | H19: SMD | I19: Metal Composite | J19: PCC | K19: LP (Low Profile) | L19: 3M-KVP | M19: PCC-M0530M-LP | N19: Yes | O19: ETQP3MR68KVP | P19: =MID(All_PCC_a[[#This Row],[Part Number]],7,3) -> R68 | Q19: 0.68 | R19: =IF(All_PCC_a[[#This Row],[Lo (uH)]]<1,"<1",IF(All_PCC_a[[#This Row],[Lo (uH)]]<10,"<10",IF(All_PCC_a[[#This Row],[Lo (uH)]]<100,"<100",IF(All_PCC_a[[#This Row],[Lo (uH)]]<2000,"<2000","")))) -> <1 | S19: =IFERROR(VLOOKUP(All_PCC_a[[#This Row],[Lo (uH)]],[1]Utility!$D$5:$E$43,2,1),"-") -> ≤ 0.7 | T19: 0.2 | U19: 7.6 | V19: 8.36 | W19: 10 | X19: 10.2 | Y19: 8.4 | Z19: 15.9 | AA19: 10.4 | AB19: 5.5 | AC19: 5 | AD19: 3 | AE19: =ROUND(All_PCC_a[[#This Row],[L (mm)]]*All_PCC_a[[#This Row],[W (mm)]],1) -> 27.5 | AF19: =All_PCC_a[[#This Row],[L (mm)]]&" x "&All_PCC_a[[#This Row],[W (mm)]] -> 5,5 x 5 | AG19: _5 x 5 | AH19: =IF(All_PCC_a[[#This Row],[Max Height (mm)]]<=9,"≤ "&ROUNDUP(AD19,0),"≤"&ROUNDUP(AD19,0)) -> ≤ 3 | AI19: -55 | AJ19: 155 | AK19: =All_PCC_a[[#This Row],[Min Temp (deg.C)]]&" to +"&All_PCC_a[[#This Row],[Max Temp (deg.C)]] -> -55 to +155 | AO19: - | AP19: =IFERROR(IF(L1Round>1,ROUND(L1Round,1),L1Round),"-") -> - | AQ19: - | AR19: - | AS19: https://industrial.panasonic.com/ww/products/pt/automotive-inductors/models/ETQP3MR68KVP | AT19: https://industrial.panasonic.com/content/data/CC/pictures/lineup-LP.gif | AU19: =_xlfn.IMAGE(All_PCC_a[[#This Row],[Image URL]]) -> #NAME? | AZ19: =IF(AY19=1,COUNTIF($AY$11:AY19,1),"") | BC19: =IF(Z19<('[1]DCDC Ref'!$J$24/'[1]DCDC Ref'!$J$26)*'[1]DCDC Ref'!$J$28/100,0,1) -> 1 | BD19: =IF(BC19=1000000000,"",('All Data'!Q19-'[1]DCDC Ref'!$J$30)/'[1]DCDC Ref'!$J$30*100) -> 7.6043956 | BE19: =ABS(BD19) -> 7.6043956 | BH19: =IF(BG19<0,10000,BG19) -> 0 | BJ19: =IF(BC19=0,"",('All Data'!Z19-'[1]DCDC Ref'!$J$28*('[1]DCDC Ref'!$J$29/100))/'[1]DCDC Ref'!$J$28*('[1]DCDC Ref'!$J$29/100)*100) -> 42.551724 | BK19: =IF(BJ19<0,10000,BJ19) -> 42.551724 | BQ19: =IFERROR(BE19*$BP$6+BK19*$BP$7,"") -> 38234.737 | BR19: =IF(BQ19="","",RANK(BQ19,BQ$11:BQ$9930,1)+COUNTIF(BQ$11:BQ19,BQ19)-1) -> 1 | BS19: =RANK(BR19,BR$11:BR$9930,1) -> 1 | BT19: =IFERROR(INDEX($O$11:$O$1013,MATCH(ROWS($BS$11:BS19),$BS$11:$BS$1005,0)),"") -> ETQP3MR47KVP | BU19: =IF(BT19<>"",BT19,"") -> ETQP3MR47KVP
A20: 70 | B20: 〇 | D20: OK | F20: MP | G20: Panasonic | H20: SMD | I20: Metal Composite | J20: PCC | K20: LP (Low Profile) | L20: 3M-KVN | M20: PCC-M0630M-LP | N20: Yes | O20: ETQP3MR68KVN | P20: =MID(All_PCC_a[[#This Row],[Part Number]],7,3) -> R68 | Q20: 0.68 | R20: =IF(All_PCC_a[[#This Row],[Lo (uH)]]<1,"<1",IF(All_PCC_a[[#This Row],[Lo (uH)]]<10,"<10",IF(All_PCC_a[[#This Row],[Lo (uH)]]<100,"<100",IF(All_PCC_a[[#This Row],[Lo (uH)]]<2000,"<2000","")))) -> <1 | S20: =IFERROR(VLOOKUP(All_PCC_a[[#This Row],[Lo (uH)]],[1]Utility!$D$5:$E$43,2,1),"-") -> ≤ 0.7 | T20: 0.2 | U20: 5.2 | V20: 5.72 | W20: 10 | X20: 13.2 | Y20: 10.8 | Z20: 20.2 | AA20: 14.25 | AB20: 6.4 | AC20: 6 | AD20: 3 | AE20: =ROUND(All_PCC_a[[#This Row],[L (mm)]]*All_PCC_a[[#This Row],[W (mm)]],1) -> 38.4 | AF20: =All_PCC_a[[#This Row],[L (mm)]]&" x "&All_PCC_a[[#This Row],[W (mm)]] -> 6,4 x 6 | AG20: _6 x 6 | AH20: =IF(All_PCC_a[[#This Row],[Max Height (mm)]]<=9,"≤ "&ROUNDUP(AD20,0),"≤"&ROUNDUP(AD20,0)) -> ≤ 3 | AI20: -55 | AJ20: 155 | AK20: =All_PCC_a[[#This Row],[Min Temp (deg.C)]]&" to +"&All_PCC_a[[#This Row],[Max Temp (deg.C)]] -> -55 to +155 | AO20: - | AP20: =IFERROR(IF(L1Round>1,ROUND(L1Round,1),L1Round),"-") -> - | AQ20: - | AR20: - | AS20: https://industrial.panasonic.com/ww/products/pt/automotive-inductors/models/ETQP3MR68KVN | AT20: https://industrial.panasonic.com/content/data/CC/pictures/lineup-LP.gif | AU20: =_xlfn.IMAGE(All_PCC_a[[#This Row],[Image URL]]) -> #NAME? | AZ20: =IF(AY20=1,COUNTIF($AY$11:AY20,1),"") | BC20: =IF(Z20<('[1]DCDC Ref'!$J$24/'[1]DCDC Ref'!$J$26)*'[1]DCDC Ref'!$J$28/100,0,1) -> 1 | BD20: =IF(BC20=1000000000,"",('All Data'!Q20-'[1]DCDC Ref'!$J$30)/'[1]DCDC Ref'!$J$30*100) -> 7.6043956 | BE20: =ABS(BD20) -> 7.6043956 | BH20: =IF(BG20<0,10000,BG20) -> 0 | BJ20: =IF(BC20=0,"",('All Data'!Z20-'[1]DCDC Ref'!$J$28*('[1]DCDC Ref'!$J$29/100))/'[1]DCDC Ref'!$J$28*('[1]DCDC Ref'!$J$29/100)*100) -> 81.103448 | BK20: =IF(BJ20<0,10000,BJ20) -> 81.103448 | BQ20: =IFERROR(BE20*$BP$6+BK20*$BP$7,"") -> 38427.495 | BR20: =IF(BQ20="","",RANK(BQ20,BQ$11:BQ$9930,1)+COUNTIF(BQ$11:BQ20,BQ20)-1) -> 2 | BS20: =RANK(BR20,BR$11:BR$9930,1) -> 2 | BT20: =IFERROR(INDEX($O$11:$O$1013,MATCH(ROWS($BS$11:BS20),$BS$11:$BS$1005,0)),"") -> ETQP3MR47KVN | BU20: =IF(BT20<>"",BT20,"") -> ETQP3MR47KVN
A21: 81 | B21: 〇 | D21: OK | F21: MP | G21: Panasonic | H21: SMD | I21: Metal Composite | J21: PCC | K21: LP (Low Profile) | L21: 4M-KVK | M21: PCC-M0840M-LP | N21: Yes | O21: ETQP4MR68KVK | P21: =MID(All_PCC_a[[#This Row],[Part Number]],7,3) -> R68 | Q21: 0.68 | R21: =IF(All_PCC_a[[#This Row],[Lo (uH)]]<1,"<1",IF(All_PCC_a[[#This Row],[Lo (uH)]]<10,"<10",IF(All_PCC_a[[#This Row],[Lo (uH)]]<100,"<100",IF(All_PCC_a[[#This Row],[Lo (uH)]]<2000,"<2000","")))) -> <1 | S21: =IFERROR(VLOOKUP(All_PCC_a[[#This Row],[Lo (uH)]],[1]Utility!$D$5:$E$43,2,1),"-") -> ≤ 0.7 | T21: 0.2 | U21: 2.92 | V21: 3.21 | W21: 10 | X21: 19.5 | Y21: 16.6 | Z21: 29 | AA21: 20.99 | AB21: 8.4 | AC21: 8 | AD21: 4 | AE21: =ROUND(All_PCC_a[[#This Row],[L (mm)]]*All_PCC_a[[#This Row],[W (mm)]],1) -> 67.2 | AF21: =All_PCC_a[[#This Row],[L (mm)]]&" x "&All_PCC_a[[#This Row],[W (mm)]] -> 8,4 x 8 | AG21: _8 x 8 | AH21: =IF(All_PCC_a[[#This Row],[Max Height (mm)]]<=9,"≤ "&ROUNDUP(AD21,0),"≤"&ROUNDUP(AD21,0)) -> ≤ 4 | AI21: -55 | AJ21: 155 | AK21: =All_PCC_a[[#This Row],[Min Temp (deg.C)]]&" to +"&All_PCC_a[[#This Row],[Max Temp (deg.C)]] -> -55 to +155 | AO21: - | AP21: =IFERROR(IF(L1Round>1,ROUND(L1Round,1),L1Round),"-") -> - | AQ21: - | AR21: - | AS21: https://industrial.panasonic.com/ww/products/pt/automotive-inductors/models/ETQP4MR68KVK | AT21: https://industrial.panasonic.com/content/data/CC/pictures/lineup-LP.gif | AU21: =_xlfn.IMAGE(All_PCC_a[[#This Row],[Image URL]]) -> #NAME? | AZ21: =IF(AY21=1,COUNTIF($AY$11:AY21,1),"") | BC21: =IF(Z21<('[1]DCDC Ref'!$J$24/'[1]DCDC Ref'!$J$26)*'[1]DCDC Ref'!$J$28/100,0,1) -> 1 | BD21: =IF(BC21=1000000000,"",('All Data'!Q21-'[1]DCDC Ref'!$J$30)/'[1]DCDC Ref'!$J$30*100) -> 7.6043956 | BE21: =ABS(BD21) -> 7.6043956 | BH21: =IF(BG21<0,10000,BG21) -> 0 | BJ21: =IF(BC21=0,"",('All Data'!Z21-'[1]DCDC Ref'!$J$28*('[1]DCDC Ref'!$J$29/100))/'[1]DCDC Ref'!$J$28*('[1]DCDC Ref'!$J$29/100)*100) -> 160 | BK21: =IF(BJ21<0,10000,BJ21) -> 160 | BQ21: =IFERROR(BE21*$BP$6+BK21*$BP$7,"") -> 38821.978 | BR21: =IF(BQ21="","",RANK(BQ21,BQ$11:BQ$9930,1)+COUNTIF(BQ$11:BQ21,BQ21)-1) -> 4 | BS21: =RANK(BR21,BR$11:BR$9930,1) -> 4 | BT21: =IFERROR(INDEX($O$11:$O$1013,MATCH(ROWS($BS$11:BS21),$BS$11:$BS$1005,0)),"") -> ETQP4MR47KFM | BU21: =IF(BT21<>"",BT21,"") -> ETQP4MR47KFM
A22: 96 | B22: 〇 | D22: OK | F22: MP | G22: Panasonic | H22: SMD | I22: Metal Composite | J22: PCC | K22: High Anti-vibration | L22: 5M-YSC | M22: PCC-M1050MS | N22: Yes | O22: ETQP5MR68YSC | P22: =MID(All_PCC_a[[#This Row],[Part Number]],7,3) -> R68 | Q22: 0.68 | R22: =IF(All_PCC_a[[#This Row],[Lo (uH)]]<1,"<1",IF(All_PCC_a[[#This Row],[Lo (uH)]]<10,"<10",IF(All_PCC_a[[#This Row],[Lo (uH)]]<100,"<100",IF(All_PCC_a[[#This Row],[Lo (uH)]]<2000,"<2000","")))) -> <1 | S22: =IFERROR(VLOOKUP(All_PCC_a[[#This Row],[Lo (uH)]],[1]Utility!$D$5:$E$43,2,1),"-") -> ≤ 0.7 | T22: 0.2 | U22: 1.66 | V22: 1.83 | W22: 10 | X22: 32.3 | Y22: 27 | Z22: 40 | AA22: 28.1 | AB22: 10.9 | AC22: 10 | AD22: 5 | AE22: =ROUND(All_PCC_a[[#This Row],[L (mm)]]*All_PCC_a[[#This Row],[W (mm)]],1) -> 109 | AF22: =All_PCC_a[[#This Row],[L (mm)]]&" x "&All_PCC_a[[#This Row],[W (mm)]] -> 10,9 x 10 | AG22: 10 x 10 | AH22: =IF(All_PCC_a[[#This Row],[Max Height (mm)]]<=9,"≤ "&ROUNDUP(AD22,0),"≤"&ROUNDUP(AD22,0)) -> ≤ 5 | AI22: -40 | AJ22: 150 | AK22: =All_PCC_a[[#This Row],[Min Temp (deg.C)]]&" to +"&All_PCC_a[[#This Row],[Max Temp (deg.C)]] -> -40 to +150 | AO22: - | AP22: =IFERROR(IF(L1Round>1,ROUND(L1Round,1),L1Round),"-") -> - | AQ22: - | AR22: - | AS22: https://industrial.panasonic.com/ww/products/pt/automotive-inductors/models/ETQP5MR68YSC | AT22: https://industrial.panasonic.com/content/data/CC/pictures/lineup-High%20Vibration%20Acceleration.gif | AU22: =_xlfn.IMAGE(All_PCC_a[[#This Row],[Image URL]]) -> #NAME? | AZ22: =IF(AY22=1,COUNTIF($AY$11:AY22,1),"") | BC22: =IF(Z22<('[1]DCDC Ref'!$J$24/'[1]DCDC Ref'!$J$26)*'[1]DCDC Ref'!$J$28/100,0,1) -> 1 | BD22: =IF(BC22=1000000000,"",('All Data'!Q22-'[1]DCDC Ref'!$J$30)/'[1]DCDC Ref'!$J$30*100) -> 7.6043956 | BE22: =ABS(BD22) -> 7.6043956 | BH22: =IF(BG22<0,10000,BG22) -> 0 | BJ22: =IF(BC22=0,"",('All Data'!Z22-'[1]DCDC Ref'!$J$28*('[1]DCDC Ref'!$J$29/100))/'[1]DCDC Ref'!$J$28*('[1]DCDC Ref'!$J$29/100)*100) -> 258.62069 | BK22: =IF(BJ22<0,10000,BJ22) -> 258.62069 | BQ22: =IFERROR(BE22*$BP$6+BK22*$BP$7,"") -> 39315.081 | BR22: =IF(BQ22="","",RANK(BQ22,BQ$11:BQ$9930,1)+COUNTIF(BQ$11:BQ22,BQ22)-1) -> 6 | BS22: =RANK(BR22,BR$11:BR$9930,1) -> 6 | BT22: =IFERROR(INDEX($O$11:$O$1013,MATCH(ROWS($BS$11:BS22),$BS$11:$BS$1005,0)),"") -> ETQP4MR47KVK | BU22: =IF(BT22<>"",BT22,"") -> ETQP4MR47KVK
A23: 2 | B23: 〇 | D23: OK | F23: MP | G23: Panasonic | H23: SMD | I23: Metal Composite | J23: PCC | K23: High Isat (Standard) | L23: 3M-YFN | M23: PCC-M0630M | N23: Yes | O23: ETQP3M1R0YFN | P23: =MID(All_PCC_a[[#This Row],[Part Number]],7,3) -> 1R0 | Q23: 1 | R23: =IF(All_PCC_a[[#This Row],[Lo (uH)]]<1,"<1",IF(All_PCC_a[[#This Row],[Lo (uH)]]<10,"<10",IF(All_PCC_a[[#This Row],[Lo (uH)]]<100,"<100",IF(All_PCC_a[[#This Row],[Lo (uH)]]<2000,"<2000","")))) -> <10 | S23: =IFERROR(VLOOKUP(All_PCC_a[[#This Row],[Lo (uH)]],[1]Utility!$D$5:$E$43,2,1),"-") -> ≤ 1 | T23: 0.2 | U23: 7.9 | V23: 8.69 | W23: 10 | X23: 10.7 | Y23: 8.8 | Z23: 20 | AA23: 14.47 | AB23: 6.5 | AC23: 6 | AD23: 3 | AE23: =ROUND(All_PCC_a[[#This Row],[L (mm)]]*All_PCC_a[[#This Row],[W (mm)]],1) -> 39 | AF23: =All_PCC_a[[#This Row],[L (mm)]]&" x "&All_PCC_a[[#This Row],[W (mm)]] -> 6,5 x 6 | AG23: _6 x 6 | AH23: =IF(All_PCC_a[[#This Row],[Max Height (mm)]]<=9,"≤ "&ROUNDUP(AD23,0),"≤"&ROUNDUP(AD23,0)) -> ≤ 3 | AI23: -40 | AJ23: 150 | AK23: =All_PCC_a[[#This Row],[Min Temp (deg.C)]]&" to +"&All_PCC_a[[#This Row],[Max Temp (deg.C)]] -> -40 to +150 | AO23: - | AP23: =IFERROR(IF(L1Round>1,ROUND(L1Round,1),L1Round),"-") -> - | AQ23: - | AR23: - | AS23: https://industrial.panasonic.com/ww/products/pt/automotive-inductors/models/ETQP3M1R0YFN | AT23: https://industrial.panasonic.com/content/data/CC/pictures/lineup-Metal-core.gif | AU23: =_xlfn.IMAGE(All_PCC_a[[#This Row],[Image URL]]) -> #NAME? | AZ23: =IF(AY23=1,COUNTIF($AY$11:AY23,1),"") | BC23: =IF(Z23<('[1]DCDC Ref'!$J$24/'[1]DCDC Ref'!$J$26)*'[1]DCDC Ref'!$J$28/100,0,1) -> 1 | BD23: =IF(BC23=1000000000,"",('All Data'!Q23-'[1]DCDC Ref'!$J$30)/'[1]DCDC Ref'!$J$30*100) -> 58.241758 | BE23: =ABS(BD23) -> 58.241758 | BH23: =IF(BG23<0,10000,BG23) -> 0 | BJ23: =IF(BC23=0,"",('All Data'!Z23-'[1]DCDC Ref'!$J$28*('[1]DCDC Ref'!$J$29/100))/'[1]DCDC Ref'!$J$28*('[1]DCDC Ref'!$J$29/100)*100) -> 79.310345 | BK23: =IF(BJ23<0,10000,BJ23) -> 79.310345 | BQ23: =IFERROR(BE23*$BP$6+BK23*$BP$7,"") -> 291605.34 | BR23: =IF(BQ23="","",RANK(BQ23,BQ$11:BQ$9930,1)+COUNTIF(BQ$11:BQ23,BQ23)-1) -> 21 | BS23: =RANK(BR23,BR$11:BR$9930,1) -> 21 | BT23: =IFERROR(INDEX($O$11:$O$1013,MATCH(ROWS($BS$11:BS23),$BS$11:$BS$1005,0)),"") -> ETQP4MR47KLC | BU23: =IF(BT23<>"",BT23,"") -> ETQP4MR47KLC
A24: 39 | B24: 〇 | D24: OK | F24: MP | G24: Panasonic | H24: SMD | I24: Metal Composite | J24: PCC | K24: High Isat (Standard) | L24: 5M-YLC | M24: PCC-M1050ML | N24: Yes | O24: ETQP5M1R0YLC | P24: =MID(All_PCC_a[[#This Row],[Part Number]],7,3) -> 1R0 | Q24: 1 | R24: =IF(All_PCC_a[[#This Row],[Lo (uH)]]<1,"<1",IF(All_PCC_a[[#This Row],[Lo (uH)]]<10,"<10",IF(All_PCC_a[[#This Row],[Lo (uH)]]<100,"<100",IF(All_PCC_a[[#This Row],[Lo (uH)]]<2000,"<2000","")))) -> <10 | S24: =IFERROR(VLOOKUP(All_PCC_a[[#This Row],[Lo (uH)]],[1]Utility!$D$5:$E$43,2,1),"-") -> ≤ 1 | T24: 0.2 | U24: 2.3 | V24: 2.53 | W24: 10 | X24: 27.5 | Y24: 23 | Z24: 37.8 | AA24: 24.6 | AB24: 10.9 | AC24: 10 | AD24: 5 | AE24: =ROUND(All_PCC_a[[#This Row],[L (mm)]]*All_PCC_a[[#This Row],[W (mm)]],1) -> 109 | AF24: =All_PCC_a[[#This Row],[L (mm)]]&" x "&All_PCC_a[[#This Row],[W (mm)]] -> 10,9 x 10 | AG24: 10 x 10 | AH24: =IF(All_PCC_a[[#This Row],[Max Height (mm)]]<=9,"≤ "&ROUNDUP(AD24,0),"≤"&ROUNDUP(AD24,0)) -> ≤ 5 | AI24: -40 | AJ24: 150 | AK24: =All_PCC_a[[#This Row],[Min Temp (deg.C)]]&" to +"&All_PCC_a[[#This Row],[Max Temp (deg.C)]] -> -40 to +150 | AO24: - | AP24: =IFERROR(IF(L1Round>1,ROUND(L1Round,1),L1Round),"-") -> - | AQ24: - | AR24: - | AS24: https://industrial.panasonic.com/ww/products/pt/automotive-inductors/models/ETQP5M1R0YLC | AT24: https://industrial.panasonic.com/content/data/CC/pictures/lineup-Metal-core.gif | AU24: =_xlfn.IMAGE(All_PCC_a[[#This Row],[Image URL]]) -> #NAME? | BC24: =IF(Z24<('[1]DCDC Ref'!$J$24/'[1]DCDC Ref'!$J$26)*'[1]DCDC Ref'!$J$28/100,0,1) -> 1 | BD24: =IF(BC24=1000000000,"",('All Data'!Q24-'[1]DCDC Ref'!$J$30)/'[1]DCDC Ref'!$J$30*100) -> 58.241758 | BE24: =ABS(BD24) -> 58.241758 | BH24: =IF(BG24<0,10000,BG24) -> 0 | BJ24: =IF(BC24=0,"",('All Data'!Z24-'[1]DCDC Ref'!$J$28*('[1]DCDC Ref'!$J$29/100))/'[1]DCDC Ref'!$J$28*('[1]DCDC Ref'!$J$29/100)*100) -> 238.89655 | BK24: =IF(BJ24<0,10000,BJ24) -> 238.89655 | BQ24: =IFERROR(BE24*$BP$6+BK24*$BP$7,"") -> 292403.27 | BR24: =IF(BQ24="","",RANK(BQ24,BQ$11:BQ$9930,1)+COUNTIF(BQ$11:BQ24,BQ24)-1) -> 24 | BS24: =RANK(BR24,BR$11:BR$9930,1) -> 24 | BT24: =IFERROR(INDEX($O$11:$O$1013,MATCH(ROWS($BS$11:BS24),$BS$11:$BS$1005,0)),"") -> ETQP3MR33KVP | BU24: =IF(BT24<>"",BT24,"") -> ETQP3MR33KVP
A25: 47 | B25: 〇 | D25: OK | F25: MP | G25: Panasonic | H25: SMD | I25: Metal Composite | J25: PCC | K25: High Current (≥□12) | L25: 8M-JFA | M25: PCC-M1280MF | N25: Yes | O25: ETQP8M1R0JFA | P25: =MID(All_PCC_a[[#This Row],[Part Number]],7,3) -> 1R0 | Q25: 1 | R25: =IF(All_PCC_a[[#This Row],[Lo (uH)]]<1,"<1",IF(All_PCC_a[[#This Row],[Lo (uH)]]<10,"<10",IF(All_PCC_a[[#This Row],[Lo (uH)]]<100,"<100",IF(All_PCC_a[[#This Row],[Lo (uH)]]<2000,"<2000","")))) -> <10 | S25: =IFERROR(VLOOKUP(All_PCC_a[[#This Row],[Lo (uH)]],[1]Utility!$D$5:$E$43,2,1),"-") -> ≤ 1 | T25: 0.2 | U25: 1.36 | V25: 1.5 | W25: 10 | X25: 38.3 | Y25: 31.8 | Z25: 44.4 | AA25: =ROUND(31.5641025641026,2) -> 31.56 | AB25: 12.6 | AC25: 13.2 | AD25: 8 | AE25: =ROUND(All_PCC_a[[#This Row],[L (mm)]]*All_PCC_a[[#This Row],[W (mm)]],1) -> 166.3 | AF25: =All_PCC_a[[#This Row],[L (mm)]]&" x "&All_PCC_a[[#This Row],[W (mm)]] -> 12,6 x 13,2 | AG25: 12 x 12 | AH25: =IF(All_PCC_a[[#This Row],[Max Height (mm)]]<=9,"≤ "&ROUNDUP(AD25,0),"≤"&ROUNDUP(AD25,0)) -> ≤ 8 | AI25: -40 | AJ25: 160 | AK25: =All_PCC_a[[#This Row],[Min Temp (deg.C)]]&" to +"&All_PCC_a[[#This Row],[Max Temp (deg.C)]] -> -40 to +160 | AN25: 15Gと聞いたがカタログは30G | AO25: - | AP25: =IFERROR(IF(L1Round>1,ROUND(L1Round,1),L1Round),"-") -> - | AQ25: - | AR25: - | AS25: https://industrial.panasonic.com/ww/products/pt/automotive-inductors/models/ETQP8M1R0JFA | AT25: https://industrial.panasonic.com/content/data/CC/pictures/lineup-Large%20current.gif | AU25: =_xlfn.IMAGE(All_PCC_a[[#This Row],[Image URL]]) -> #NAME? | AZ25: =IF(AY25=1,COUNTIF($AY$11:AY25,1),"") | BC25: =IF(Z25<('[1]DCDC Ref'!$J$24/'[1]DCDC Ref'!$J$26)*'[1]DCDC Ref'!$J$28/100,0,1) -> 1 | BD25: =IF(BC25=1000000000,"",('All Data'!Q25-'[1]DCDC Ref'!$J$30)/'[1]DCDC Ref'!$J$30*100) -> 58.241758 | BE25: =ABS(BD25) -> 58.241758 | BH25: =IF(BG25<0,10000,BG25) -> 0 | BJ25: =IF(BC25=0,"",('All Data'!Z25-'[1]DCDC Ref'!$J$28*('[1]DCDC Ref'!$J$29/100))/'[1]DCDC Ref'!$J$28*('[1]DCDC Ref'!$J$29/100)*100) -> 298.06897 | BK25: =IF(BJ25<0,10000,BJ25) -> 298.06897 | BQ25: =IFERROR(BE25*$BP$6+BK25*$BP$7,"") -> 292699.14 | BR25: =IF(BQ25="","",RANK(BQ25,BQ$11:BQ$9930,1)+COUNTIF(BQ$11:BQ25,BQ25)-1) -> 25 | BS25: =RANK(BR25,BR$11:BR$9930,1) -> 25 | BT25: =IFERROR(INDEX($O$11:$O$1013,MATCH(ROWS($BS$11:BS25),$BS$11:$BS$1005,0)),"") -> ETQP4MR33KLC | BU25: =IF(BT25<>"",BT25,"") -> ETQP4MR33KLC
A26: 58 | B26: 〇 | D26: OK | F26: MP | G26: Panasonic | H26: SMD | I26: Metal Composite | J26: PCC | K26: LP (Low Profile) | L26: 3M-KVP | M26: PCC-M0530M-LP | N26: Yes | O26: ETQP3M1R0KVP | P26: =MID(All_PCC_a[[#This Row],[Part Number]],7,3) -> 1R0 | Q26: 1 | R26: =IF(All_PCC_a[[#This Row],[Lo (uH)]]<1,"<1",IF(All_PCC_a[[#This Row],[Lo (uH)]]<10,"<10",IF(All_PCC_a[[#This Row],[Lo (uH)]]<100,"<100",IF(All_PCC_a[[#This Row],[Lo (uH)]]<2000,"<2000","")))) -> <10 | S26: =IFERROR(VLOOKUP(All_PCC_a[[#This Row],[Lo (uH)]],[1]Utility!$D$5:$E$43,2,1),"-") -> ≤ 1 | T26: 0.2 | U26: 9.6 | V26: 10.56 | W26: 10 | X26: 9 | Y26: 7.5 | Z26: 14.1 | AA26: 10.4 | AB26: 5.5 | AC26: 5 | AD26: 3 | AE26: =ROUND(All_PCC_a[[#This Row],[L (mm)]]*All_PCC_a[[#This Row],[W (mm)]],1) -> 27.5 | AF26: =All_PCC_a[[#This Row],[L (mm)]]&" x "&All_PCC_a[[#This Row],[W (mm)]] -> 5,5 x 5 | AG26: _5 x 5 | AH26: =IF(All_PCC_a[[#This Row],[Max Height (mm)]]<=9,"≤ "&ROUNDUP(AD26,0),"≤"&ROUNDUP(AD26,0)) -> ≤ 3 | AI26: -55 | AJ26: 155 | AK26: =All_PCC_a[[#This Row],[Min Temp (deg.C)]]&" to +"&All_PCC_a[[#This Row],[Max Temp (deg.C)]] -> -55 to +155 | AO26: - | AP26: =IFERROR(IF(L1Round>1,ROUND(L1Round,1),L1Round),"-") -> - | AQ26: - | AR26: - | AS26: https://industrial.panasonic.com/ww/products/pt/automotive-inductors/models/ETQP3M1R0KVP | AT26: https://industrial.panasonic.com/content/data/CC/pictures/lineup-LP.gif | AU26: =_xlfn.IMAGE(All_PCC_a[[#This Row],[Image URL]]) -> #NAME? | AZ26: =IF(AY26=1,COUNTIF($AY$11:AY26,1),"") | BC26: =IF(Z26<('[1]DCDC Ref'!$J$24/'[1]DCDC Ref'!$J$26)*'[1]DCDC Ref'!$J$28/100,0,1) -> 1 | BD26: =IF(BC26=1000000000,"",('All Data'!Q26-'[1]DCDC Ref'!$J$30)/'[1]DCDC Ref'!$J$30*100) -> 58.241758 | BE26: =ABS(BD26) -> 58.241758 | BH26: =IF(BG26<0,10000,BG26) -> 0 | BJ26: =IF(BC26=0,"",('All Data'!Z26-'[1]DCDC Ref'!$J$28*('[1]DCDC Ref'!$J$29/100))/'[1]DCDC Ref'!$J$28*('[1]DCDC Ref'!$J$29/100)*100) -> 26.413793 | BK26: =IF(BJ26<0,10000,BJ26) -> 26.413793 | BQ26: =IFERROR(BE26*$BP$6+BK26*$BP$7,"") -> 291340.86 | BR26: =IF(BQ26="","",RANK(BQ26,BQ$11:BQ$9930,1)+COUNTIF(BQ$11:BQ26,BQ26)-1) -> 19 | BS26: =RANK(BR26,BR$11:BR$9930,1) -> 19 | BT26: =IFERROR(INDEX($O$11:$O$1013,MATCH(ROWS($BS$11:BS26),$BS$11:$BS$1005,0)),"") -> ETQP5MR33YLC | BU26: =IF(BT26<>"",BT26,"") -> ETQP5MR33YLC
A27: 69 | B27: 〇 | D27: OK | F27: MP | G27: Panasonic | H27: SMD | I27: Metal Composite | J27: PCC | K27: LP (Low Profile) | L27: 3M-KVN | M27: PCC-M0630M-LP | N27: Yes | O27: ETQP3M1R0KVN | P27: =MID(All_PCC_a[[#This Row],[Part Number]],7,3) -> 1R0 | Q27: 1 | R27: =IF(All_PCC_a[[#This Row],[Lo (uH)]]<1,"<1",IF(All_PCC_a[[#This Row],[Lo (uH)]]<10,"<10",IF(All_PCC_a[[#This Row],[Lo (uH)]]<100,"<100",IF(All_PCC_a[[#This Row],[Lo (uH)]]<2000,"<2000","")))) -> <10 | S27: =IFERROR(VLOOKUP(All_PCC_a[[#This Row],[Lo (uH)]],[1]Utility!$D$5:$E$43,2,1),"-") -> ≤ 1 | T27: 0.2 | U27: 6.2 | V27: 6.82 | W27: 10 | X27: 12.1 | Y27: 9.9 | Z27: 16 | AA27: 10.65 | AB27: 6.4 | AC27: 6 | AD27: 3 | AE27: =ROUND(All_PCC_a[[#This Row],[L (mm)]]*All_PCC_a[[#This Row],[W (mm)]],1) -> 38.4 | AF27: =All_PCC_a[[#This Row],[L (mm)]]&" x "&All_PCC_a[[#This Row],[W (mm)]] -> 6,4 x 6 | AG27: _6 x 6 | AH27: =IF(All_PCC_a[[#This Row],[Max Height (mm)]]<=9,"≤ "&ROUNDUP(AD27,0),"≤"&ROUNDUP(AD27,0)) -> ≤ 3 | AI27: -55 | AJ27: 155 | AK27: =All_PCC_a[[#This Row],[Min Temp (deg.C)]]&" to +"&All_PCC_a[[#This Row],[Max Temp (deg.C)]] -> -55 to +155 | AO27: - | AP27: =IFERROR(IF(L1Round>1,ROUND(L1Round,1),L1Round),"-") -> - | AQ27: - | AR27: - | AS27: https://industrial.panasonic.com/ww/products/pt/automotive-inductors/models/ETQP3M1R0KVN | AT27: https://industrial.panasonic.com/content/data/CC/pictures/lineup-LP.gif | AU27: =_xlfn.IMAGE(All_PCC_a[[#This Row],[Image URL]]) -> #NAME? | AZ27: =IF(AY27=1,COUNTIF($AY$11:AY27,1),"") | BC27: =IF(Z27<('[1]DCDC Ref'!$J$24/'[1]DCDC Ref'!$J$26)*'[1]DCDC Ref'!$J$28/100,0,1) -> 1 | BD27: =IF(BC27=1000000000,"",('All Data'!Q27-'[1]DCDC Ref'!$J$30)/'[1]DCDC Ref'!$J$30*100) -> 58.241758 | BE27: =ABS(BD27) -> 58.241758 | BH27: =IF(BG27<0,10000,BG27) -> 0 | BJ27: =IF(BC27=0,"",('All Data'!Z27-'[1]DCDC Ref'!$J$28*('[1]DCDC Ref'!$J$29/100))/'[1]DCDC Ref'!$J$28*('[1]DCDC Ref'!$J$29/100)*100) -> 43.448276 | BK27: =IF(BJ27<0,10000,BJ27) -> 43.448276 | BQ27: =IFERROR(BE27*$BP$6+BK27*$BP$7,"") -> 291426.03 | BR27: =IF(BQ27="","",RANK(BQ27,BQ$11:BQ$9930,1)+COUNTIF(BQ$11:BQ27,BQ27)-1) -> 20 | BS27: =RANK(BR27,BR$11:BR$9930,1) -> 20 | BT27: =IFERROR(INDEX($O$11:$O$1013,MATCH(ROWS($BS$11:BS27),$BS$11:$BS$1005,0)),"") -> ETQP8MR33JFA | BU27: =IF(BT27<>"",BT27,"") -> ETQP8MR33JFA
A28: 80 | B28: 〇 | D28: OK | F28: MP | G28: Panasonic | H28: SMD | I28: Metal Composite | J28: PCC | K28: LP (Low Profile) | L28: 4M-KVK | M28: PCC-M0840M-LP | N28: Yes | O28: ETQP4M1R0KVK | P28: =MID(All_PCC_a[[#This Row],[Part Number]],7,3) -> 1R0 | Q28: 1 | R28: =IF(All_PCC_a[[#This Row],[Lo (uH)]]<1,"<1",IF(All_PCC_a[[#This Row],[Lo (uH)]]<10,"<10",IF(All_PCC_a[[#This Row],[Lo (uH)]]<100,"<100",IF(All_PCC_a[[#This Row],[Lo (uH)]]<2000,"<2000","")))) -> <10 | S28: =IFERROR(VLOOKUP(All_PCC_a[[#This Row],[Lo (uH)]],[1]Utility!$D$5:$E$43,2,1),"-") -> ≤ 1 | T28: 0.2 | U28: 3.7 | V28: 4.07 | W28: 10 | X28: 17.3 | Y28: 14.8 | Z28: 24.4 | AA28: 19.06 | AB28: 8.4 | AC28: 8 | AD28: 4 | AE28: =ROUND(All_PCC_a[[#This Row],[L (mm)]]*All_PCC_a[[#This Row],[W (mm)]],1) -> 67.2 | AF28: =All_PCC_a[[#This Row],[L (mm)]]&" x "&All_PCC_a[[#This Row],[W (mm)]] -> 8,4 x 8 | AG28: _8 x 8 | AH28: =IF(All_PCC_a[[#This Row],[Max Height (mm)]]<=9,"≤ "&ROUNDUP(AD28,0),"≤"&ROUNDUP(AD28,0)) -> ≤ 4 | AI28: -55 | AJ28: 155 | AK28: =All_PCC_a[[#This Row],[Min Temp (deg.C)]]&" to +"&All_PCC_a[[#This Row],[Max Temp (deg.C)]] -> -55 to +155 | AO28: - | AP28: =IFERROR(IF(L1Round>1,ROUND(L1Round,1),L1Round),"-") -> - | AQ28: - | AR28: - | AS28: https://industrial.panasonic.com/ww/products/pt/automotive-inductors/models/ETQP4M1R0KVK | AT28: https://industrial.panasonic.com/content/data/CC/pictures/lineup-LP.gif | AU28: =_xlfn.IMAGE(All_PCC_a[[#This Row],[Image URL]]) -> #NAME? | BC28: =IF(Z28<('[1]DCDC Ref'!$J$24/'[1]DCDC Ref'!$J$26)*'[1]DCDC Ref'!$J$28/100,0,1) -> 1 | BD28: =IF(BC28=1000000000,"",('All Data'!Q28-'[1]DCDC Ref'!$J$30)/'[1]DCDC Ref'!$J$30*100) -> 58.241758 | BE28: =ABS(BD28) -> 58.241758 | BH28: =IF(BG28<0,10000,BG28) -> 0 | BJ28: =IF(BC28=0,"",('All Data'!Z28-'[1]DCDC Ref'!$J$28*('[1]DCDC Ref'!$J$29/100))/'[1]DCDC Ref'!$J$28*('[1]DCDC Ref'!$J$29/100)*100) -> 118.75862 | BK28: =IF(BJ28<0,10000,BJ28) -> 118.75862 | BQ28: =IFERROR(BE28*$BP$6+BK28*$BP$7,"") -> 291802.58 | BR28: =IF(BQ28="","",RANK(BQ28,BQ$11:BQ$9930,1)+COUNTIF(BQ$11:BQ28,BQ28)-1) -> 22 | BS28: =RANK(BR28,BR$11:BR$9930,1) -> 22 | BT28: =IFERROR(INDEX($O$11:$O$1013,MATCH(ROWS($BS$11:BS28),$BS$11:$BS$1005,0)),"") -> ETQPAMR33JFW | BU28: =IF(BT28<>"",BT28,"") -> ETQPAMR33JFW
A29: 92 | B29: 〇 | D29: OK | F29: MP | G29: Panasonic | H29: SMD | I29: Metal Composite | J29: PCC | K29: LP (Low Profile) | L29: 4M-KVC | M29: PCC-M1040M-LP | N29: Yes | O29: ETQP4M1R0KVC | P29: =MID(All_PCC_a[[#This Row],[Part Number]],7,3) -> 1R0 | Q29: 1 | R29: =IF(All_PCC_a[[#This Row],[Lo (uH)]]<1,"<1",IF(All_PCC_a[[#This Row],[Lo (uH)]]<10,"<10",IF(All_PCC_a[[#This Row],[Lo (uH)]]<100,"<100",IF(All_PCC_a[[#This Row],[Lo (uH)]]<2000,"<2000","")))) -> <10 | S29: =IFERROR(VLOOKUP(All_PCC_a[[#This Row],[Lo (uH)]],[1]Utility!$D$5:$E$43,2,1),"-") -> ≤ 1 | T29: 0.2 | U29: 2.6 | V29: 2.86 | W29: 10 | X29: 23.9 | Y29: 19.6 | Z29: 34.6 | AA29: 24 | AB29: 10.7 | AC29: 10 | AD29: 4 | AE29: =ROUND(All_PCC_a[[#This Row],[L (mm)]]*All_PCC_a[[#This Row],[W (mm)]],1) -> 107 | AF29: =All_PCC_a[[#This Row],[L (mm)]]&" x "&All_PCC_a[[#This Row],[W (mm)]] -> 10,7 x 10 | AG29: 10 x 10 | AH29: =IF(All_PCC_a[[#This Row],[Max Height (mm)]]<=9,"≤ "&ROUNDUP(AD29,0),"≤"&ROUNDUP(AD29,0)) -> ≤ 4 | AI29: -55 | AJ29: 155 | AK29: =All_PCC_a[[#This Row],[Min Temp (deg.C)]]&" to +"&All_PCC_a[[#This Row],[Max Temp (deg.C)]] -> -55 to +155 | AO29: - | AP29: =IFERROR(IF(L1Round>1,ROUND(L1Round,1),L1Round),"-") -> - | AQ29: - | AR29: - | AS29: https://industrial.panasonic.com/ww/products/pt/automotive-inductors/models/ETQP4M1R0KVC | AT29: https://industrial.panasonic.com/content/data/CC/pictures/lineup-LP.gif | AU29: =_xlfn.IMAGE(All_PCC_a[[#This Row],[Image URL]]) -> #NAME? | AZ29: =IF(AY29=1,COUNTIF($AY$11:AY29,1),"") | BC29: =IF(Z29<('[1]DCDC Ref'!$J$24/'[1]DCDC Ref'!$J$26)*'[1]DCDC Ref'!$J$28/100,0,1) -> 1 | BD29: =IF(BC29=1000000000,"",('All Data'!Q29-'[1]DCDC Ref'!$J$30)/'[1]DCDC Ref'!$J$30*100) -> 58.241758 | BE29: =ABS(BD29) -> 58.241758 | BH29: =IF(BG29<0,10000,BG29) -> 0 | BJ29: =IF(BC29=0,"",('All Data'!Z29-'[1]DCDC Ref'!$J$28*('[1]DCDC Ref'!$J$29/100))/'[1]DCDC Ref'!$J$28*('[1]DCDC Ref'!$J$29/100)*100) -> 210.2069 | BK29: =IF(BJ29<0,10000,BJ29) -> 210.2069 | BQ29: =IFERROR(BE29*$BP$6+BK29*$BP$7,"") -> 292259.83 | BR29: =IF(BQ29="","",RANK(BQ29,BQ$11:BQ$9930,1)+COUNTIF(BQ$11:BQ29,BQ29)-1) -> 23 | BS29: =RANK(BR29,BR$11:BR$9930,1) -> 23 | BT29: =IFERROR(INDEX($O$11:$O$1013,MATCH(ROWS($BS$11:BS29),$BS$11:$BS$1005,0)),"") -> ETQP3M1R0KVP | BU29: =IF(BT29<>"",BT29,"") -> ETQP3M1R0KVP
A30: 13 | B30: 〇 | D30: OK | F30: MP | G30: Panasonic | H30: SMD | I30: Metal Composite | J30: PCC | K30: High Isat (Standard) | L30: 5M-YFC | M30: PCC-M1054M | N30: Yes | O30: ETQP5M1R5YFC | P30: =MID(All_PCC_a[[#This Row],[Part Number]],7,3) -> 1R5 | Q30: 1.5 | R30: =IF(All_PCC_a[[#This Row],[Lo (uH)]]<1,"<1",IF(All_PCC_a[[#This Row],[Lo (uH)]]<10,"<10",IF(All_PCC_a[[#This Row],[Lo (uH)]]<100,"<100",IF(All_PCC_a[[#This Row],[Lo (uH)]]<2000,"<2000","")))) -> <10 | S30: =IFERROR(VLOOKUP(All_PCC_a[[#This Row],[Lo (uH)]],[1]Utility!$D$5:$E$43,2,1),"-") -> ≤ 2 | T30: 0.2 | U30: 3.8 | V30: 4.18 | W30: 10 | X30: 21.4 | Y30: 17.9 | Z30: 35.1 | AA30: 25.52 | AB30: 10.7 | AC30: 10 | AD30: 5.4 | AE30: =ROUND(All_PCC_a[[#This Row],[L (mm)]]*All_PCC_a[[#This Row],[W (mm)]],1) -> 107 | AF30: =All_PCC_a[[#This Row],[L (mm)]]&" x "&All_PCC_a[[#This Row],[W (mm)]] -> 10,7 x 10 | AG30: 10 x 10 | AH30: =IF(All_PCC_a[[#This Row],[Max Height (mm)]]<=9,"≤ "&ROUNDUP(AD30,0),"≤"&ROUNDUP(AD30,0)) -> ≤ 6 | AI30: -40 | AJ30: 150 | AK30: =All_PCC_a[[#This Row],[Min Temp (deg.C)]]&" to +"&All_PCC_a[[#This Row],[Max Temp (deg.C)]] -> -40 to +150 | AO30: - | AP30: =IFERROR(IF(L1Round>1,ROUND(L1Round,1),L1Round),"-") -> - | AQ30: - | AR30: - | AS30: https://industrial.panasonic.com/ww/products/pt/automotive-inductors/models/ETQP5M1R5YFC | AT30: https://industrial.panasonic.com/content/data/CC/pictures/lineup-Metal-core.gif | AU30: =_xlfn.IMAGE(All_PCC_a[[#This Row],[Image URL]]) -> #NAME? | AZ30: =IF(AY30=1,COUNTIF($AY$11:AY30,1),"") | BC30: =IF(Z30<('[1]DCDC Ref'!$J$24/'[1]DCDC Ref'!$J$26)*'[1]DCDC Ref'!$J$28/100,0,1) -> 1 | BD30: =IF(BC30=1000000000,"",('All Data'!Q30-'[1]DCDC Ref'!$J$30)/'[1]DCDC Ref'!$J$30*100) -> 137.36264 | BE30: =ABS(BD30) -> 137.36264 | BH30: =IF(BG30<0,10000,BG30) -> 0 | BJ30: =IF(BC30=0,"",('All Data'!Z30-'[1]DCDC Ref'!$J$28*('[1]DCDC Ref'!$J$29/100))/'[1]DCDC Ref'!$J$28*('[1]DCDC Ref'!$J$29/100)*100) -> 214.68966 | BK30: =IF(BJ30<0,10000,BJ30) -> 214.68966 | BQ30: =IFERROR(BE30*$BP$6+BK30*$BP$7,"") -> 687886.64 | BR30: =IF(BQ30="","",RANK(BQ30,BQ$11:BQ$9930,1)+COUNTIF(BQ$11:BQ30,BQ30)-1) -> 37 | BS30: =RANK(BR30,BR$11:BR$9930,1) -> 37 | BT30: =IFERROR(INDEX($O$11:$O$1013,MATCH(ROWS($BS$11:BS30),$BS$11:$BS$1005,0)),"") -> ETQP3M1R0KVN | BU30: =IF(BT30<>"",BT30,"") -> ETQP3M1R0KVN
A31: 41 | B31: 〇 | D31: OK | F31: MP | G31: Panasonic | H31: SMD | I31: Metal Composite | J31: PCC | K31: High Isat (Standard) | L31: 6M-YLC | M31: PCC-M1060ML | N31: Yes | O31: ETQP6M1R5YLC | P31: =MID(All_PCC_a[[#This Row],[Part Number]],7,3) -> 1R5 | Q31: 1.5 | R31: =IF(All_PCC_a[[#This Row],[Lo (uH)]]<1,"<1",IF(All_PCC_a[[#This Row],[Lo (uH)]]<10,"<10",IF(All_PCC_a[[#This Row],[Lo (uH)]]<100,"<100",IF(All_PCC_a[[#This Row],[Lo (uH)]]<2000,"<2000","")))) -> <10 | S31: =IFERROR(VLOOKUP(All_PCC_a[[#This Row],[Lo (uH)]],[1]Utility!$D$5:$E$43,2,1),"-") -> ≤ 2 | T31: 0.2 | U31: 3.2 | V31: 3.52 | W31: 10 | X31: 23.3 | Y31: 19.5 | Z31: 32 | AA31: 22.19 | AB31: 10.9 | AC31: 10 | AD31: 6 | AE31: =ROUND(All_PCC_a[[#This Row],[L (mm)]]*All_PCC_a[[#This Row],[W (mm)]],1) -> 109 | AF31: =All_PCC_a[[#This Row],[L (mm)]]&" x "&All_PCC_a[[#This Row],[W (mm)]] -> 10,9 x 10 | AG31: 10 x 10 | AH31: =IF(All_PCC_a[[#This Row],[Max Height (mm)]]<=9,"≤ "&ROUNDUP(AD31,0),"≤"&ROUNDUP(AD31,0)) -> ≤ 6 | AI31: -40 | AJ31: 150 | AK31: =All_PCC_a[[#This Row],[Min Temp (deg.C)]]&" to +"&All_PCC_a[[#This Row],[Max Temp (deg.C)]] -> -40 to +150 | AO31: - | AP31: =IFERROR(IF(L1Round>1,ROUND(L1Round,1),L1Round),"-") -> - | AQ31: - | AR31: - | AS31: https://industrial.panasonic.com/ww/products/pt/automotive-inductors/models/ETQP6M1R5YLC | AT31: https://industrial.panasonic.com/content/data/CC/pictures/lineup-Metal-core.gif | AU31: =_xlfn.IMAGE(All_PCC_a[[#This Row],[Image URL]]) -> #NAME? | BC31: =IF(Z31<('[1]DCDC Ref'!$J$24/'[1]DCDC Ref'!$J$26)*'[1]DCDC Ref'!$J$28/100,0,1) -> 1 | BD31: =IF(BC31=1000000000,"",('All Data'!Q31-'[1]DCDC Ref'!$J$30)/'[1]DCDC Ref'!$J$30*100) -> 137.36264 | BE31: =ABS(BD31) -> 137.36264 | BH31: =IF(BG31<0,10000,BG31) -> 0 | BJ31: =IF(BC31=0,"",('All Data'!Z31-'[1]DCDC Ref'!$J$28*('[1]DCDC Ref'!$J$29/100))/'[1]DCDC Ref'!$J$28*('[1]DCDC Ref'!$J$29/100)*100) -> 186.89655 | BK31: =IF(BJ31<0,10000,BJ31) -> 186.89655 | BQ31: =IFERROR(BE31*$BP$6+BK31*$BP$7,"") -> 687747.67 | BR31: =IF(BQ31="","",RANK(BQ31,BQ$11:BQ$9930,1)+COUNTIF(BQ$11:BQ31,BQ31)-1) -> 36 | BS31: =RANK(BR31,BR$11:BR$9930,1) -> 36 | BT31: =IFERROR(INDEX($O$11:$O$1013,MATCH(ROWS($BS$11:BS31),$BS$11:$BS$1005,0)),"") -> ETQP3M1R0YFN | BU31: =IF(BT31<>"",BT31,"") -> ETQP3M1R0YFN
A32: 48 | B32: 〇 | D32: OK | F32: MP | G32: Panasonic | H32: SMD | I32: Metal Composite | J32: PCC | K32: High Current (≥□12) | L32: 8M-JFA | M32: PCC-M1280MF | N32: Yes | O32: ETQP8M1R5JFA | P32: =MID(All_PCC_a[[#This Row],[Part Number]],7,3) -> 1R5 | Q32: 1.5 | R32: =IF(All_PCC_a[[#This Row],[Lo (uH)]]<1,"<1",IF(All_PCC_a[[#This Row],[Lo (uH)]]<10,"<10",IF(All_PCC_a[[#This Row],[Lo (uH)]]<100,"<100",IF(All_PCC_a[[#This Row],[Lo (uH)]]<2000,"<2000","")))) -> <10 | S32: =IFERROR(VLOOKUP(All_PCC_a[[#This Row],[Lo (uH)]],[1]Utility!$D$5:$E$43,2,1),"-") -> ≤ 2 | T32: 0.2 | U32: 1.8 | V32: 1.98 | W32: 10 | X32: 33.3 | Y32: 27.7 | Z32: 29.9 | AA32: 21.51 | AB32: 12.6 | AC32: 13.2 | AD32: 8 | AE32: =ROUND(All_PCC_a[[#This Row],[L (mm)]]*All_PCC_a[[#This Row],[W (mm)]],1) -> 166.3 | AF32: =All_PCC_a[[#This Row],[L (mm)]]&" x "&All_PCC_a[[#This Row],[W (mm)]] -> 12,6 x 13,2 | AG32: 12 x 12 | AH32: =IF(All_PCC_a[[#This Row],[Max Height (mm)]]<=9,"≤ "&ROUNDUP(AD32,0),"≤"&ROUNDUP(AD32,0)) -> ≤ 8 | AI32: -40 | AJ32: 160 | AK32: =All_PCC_a[[#This Row],[Min Temp (deg.C)]]&" to +"&All_PCC_a[[#This Row],[Max Temp (deg.C)]] -> -40 to +160 | AN32: 15Gと聞いたがカタログは30G | AO32: - | AP32: =IFERROR(IF(L1Round>1,ROUND(L1Round,1),L1Round),"-") -> - | AQ32: - | AR32: - | AS32: https://industrial.panasonic.com/ww/products/pt/automotive-inductors/models/ETQP8M1R5JFA | AT32: https://industrial.panasonic.com/content/data/CC/pictures/lineup-Large%20current.gif | AU32: =_xlfn.IMAGE(All_PCC_a[[#This Row],[Image URL]]) -> #NAME? | BC32: =IF(Z32<('[1]DCDC Ref'!$J$24/'[1]DCDC Ref'!$J$26)*'[1]DCDC Ref'!$J$28/100,0,1) -> 1 | BD32: =IF(BC32=1000000000,"",('All Data'!Q32-'[1]DCDC Ref'!$J$30)/'[1]DCDC Ref'!$J$30*100) -> 137.36264 | BE32: =ABS(BD32) -> 137.36264 | BH32: =IF(BG32<0,10000,BG32) -> 0 | BJ32: =IF(BC32=0,"",('All Data'!Z32-'[1]DCDC Ref'!$J$28*('[1]DCDC Ref'!$J$29/100))/'[1]DCDC Ref'!$J$28*('[1]DCDC Ref'!$J$29/100)*100) -> 168.06897 | BK32: =IF(BJ32<0,10000,BJ32) -> 168.06897 | BQ32: =IFERROR(BE32*$BP$6+BK32*$BP$7,"") -> 687653.53 | BR32: =IF(BQ32="","",RANK(BQ32,BQ$11:BQ$9930,1)+COUNTIF(BQ$11:BQ32,BQ32)-1) -> 35 | BS32: =RANK(BR32,BR$11:BR$9930,1) -> 35 | BT32: =IFERROR(INDEX($O$11:$O$1013,MATCH(ROWS($BS$11:BS32),$BS$11:$BS$1005,0)),"") -> ETQP4M1R0KVK | BU32: =IF(BT32<>"",BT32,"") -> ETQP4M1R0KVK
A33: 57 | B33: 〇 | D33: OK | F33: MP | G33: Panasonic | H33: SMD | I33: Metal Composite | J33: PCC | K33: LP (Low Profile) | L33: 3M-KVP | M33: PCC-M0530M-LP | N33: Yes | O33: ETQP3M1R5KVP | P33: =MID(All_PCC_a[[#This Row],[Part Number]],7,3) -> 1R5 | Q33: 1.5 | R33: =IF(All_PCC_a[[#This Row],[Lo (uH)]]<1,"<1",IF(All_PCC_a[[#This Row],[Lo (uH)]]<10,"<10",IF(All_PCC_a[[#This Row],[Lo (uH)]]<100,"<100",IF(All_PCC_a[[#This Row],[Lo (uH)]]<2000,"<2000","")))) -> <10 | S33: =IFERROR(VLOOKUP(All_PCC_a[[#This Row],[Lo (uH)]],[1]Utility!$D$5:$E$43,2,1),"-") -> ≤ 2 | T33: 0.2 | U33: 12 | V33: 13.2 | W33: 10 | X33: 8.1 | Y33: 6.7 | Z33: 12 | AA33: 9.61 | AB33: 5.5 | AC33: 5 | AD33: 3 | AE33: =ROUND(All_PCC_a[[#This Row],[L (mm)]]*All_PCC_a[[#This Row],[W (mm)]],1) -> 27.5 | AF33: =All_PCC_a[[#This Row],[L (mm)]]&" x "&All_PCC_a[[#This Row],[W (mm)]] -> 5,5 x 5 | AG33: _5 x 5 | AH33: =IF(All_PCC_a[[#This Row],[Max Height (mm)]]<=9,"≤ "&ROUNDUP(AD33,0),"≤"&ROUNDUP(AD33,0)) -> ≤ 3 | AI33: -55 | AJ33: 155 | AK33: =All_PCC_a[[#This Row],[Min Temp (deg.C)]]&" to +"&All_PCC_a[[#This Row],[Max Temp (deg.C)]] -> -55 to +155 | AO33: - | AP33: =IFERROR(IF(L1Round>1,ROUND(L1Round,1),L1Round),"-") -> - | AQ33: - | AR33: - | AS33: https://industrial.panasonic.com/ww/products/pt/automotive-inductors/models/ETQP3M1R5KVP | AT33: https://industrial.panasonic.com/content/data/CC/pictures/lineup-LP.gif | AU33: =_xlfn.IMAGE(All_PCC_a[[#This Row],[Image URL]]) -> #NAME? | AZ33: =IF(AY33=1,COUNTIF($AY$11:AY33,1),"") | BC33: =IF(Z33<('[1]DCDC Ref'!$J$24/'[1]DCDC Ref'!$J$26)*'[1]DCDC Ref'!$J$28/100,0,1) -> 1 | BD33: =IF(BC33=1000000000,"",('All Data'!Q33-'[1]DCDC Ref'!$J$30)/'[1]DCDC Ref'!$J$30*100) -> 137.36264 | BE33: =ABS(BD33) -> 137.36264 | BH33: =IF(BG33<0,10000,BG33) -> 0 | BJ33: =IF(BC33=0,"",('All Data'!Z33-'[1]DCDC Ref'!$J$28*('[1]DCDC Ref'!$J$29/100))/'[1]DCDC Ref'!$J$28*('[1]DCDC Ref'!$J$29/100)*100) -> 7.5862069 | BK33: =IF(BJ33<0,10000,BJ33) -> 7.5862069 | BQ33: =IFERROR(BE33*$BP$6+BK33*$BP$7,"") -> 686851.12 | BR33: =IF(BQ33="","",RANK(BQ33,BQ$11:BQ$9930,1)+COUNTIF(BQ$11:BQ33,BQ33)-1) -> 30 | BS33: =RANK(BR33,BR$11:BR$9930,1) -> 30 | BT33: =IFERROR(INDEX($O$11:$O$1013,MATCH(ROWS($BS$11:BS33),$BS$11:$BS$1005,0)),"") -> ETQP4M1R0KVC | BU33: =IF(BT33<>"",BT33,"") -> ETQP4M1R0KVC
A34: 68 | B34: 〇 | D34: OK | F34: MP | G34: Panasonic | H34: SMD | I34: Metal Composite | J34: PCC | K34: LP (Low Profile) | L34: 3M-KVN | M34: PCC-M0630M-LP | N34: Yes | O34: ETQP3M1R5KVN | P34: =MID(All_PCC_a[[#This Row],[Part Number]],7,3) -> 1R5 | Q34: 1.5 | R34: =IF(All_PCC_a[[#This Row],[Lo (uH)]]<1,"<1",IF(All_PCC_a[[#This Row],[Lo (uH)]]<10,"<10",IF(All_PCC_a[[#This Row],[Lo (uH)]]<100,"<100",IF(All_PCC_a[[#This Row],[Lo (uH)]]<2000,"<2000","")))) -> <10 | S34: =IFERROR(VLOOKUP(All_PCC_a[[#This Row],[Lo (uH)]],[1]Utility!$D$5:$E$43,2,1),"-") -> ≤ 2 | T34: 0.2 | U34: 11 | V34: 12.1 | W34: 10 | X34: 9.1 | Y34: 7.4 | Z34: 14.2 | AA34: 10.37 | AB34: 6.4 | AC34: 6 | AD34: 3 | AE34: =ROUND(All_PCC_a[[#This Row],[L (mm)]]*All_PCC_a[[#This Row],[W (mm)]],1) -> 38.4 | AF34: =All_PCC_a[[#This Row],[L (mm)]]&" x "&All_PCC_a[[#This Row],[W (mm)]] -> 6,4 x 6 | AG34: _6 x 6 | AH34: =IF(All_PCC_a[[#This Row],[Max Height (mm)]]<=9,"≤ "&ROUNDUP(AD34,0),"≤"&ROUNDUP(AD34,0)) -> ≤ 3 | AI34: -55 | AJ34: 155 | AK34: =All_PCC_a[[#This Row],[Min Temp (deg.C)]]&" to +"&All_PCC_a[[#This Row],[Max Temp (deg.C)]] -> -55 to +155 | AO34: - | AP34: =IFERROR(IF(L1Round>1,ROUND(L1Round,1),L1Round),"-") -> - | AQ34: - | AR34: - | AS34: https://industrial.panasonic.com/ww/products/pt/automotive-inductors/models/ETQP3M1R5KVN | AT34: https://industrial.panasonic.com/content/data/CC/pictures/lineup-LP.gif | AU34: =_xlfn.IMAGE(All_PCC_a[[#This Row],[Image URL]]) -> #NAME? | AZ34: =IF(AY34=1,COUNTIF($AY$11:AY34,1),"") | BC34: =IF(Z34<('[1]DCDC Ref'!$J$24/'[1]DCDC Ref'!$J$26)*'[1]DCDC Ref'!$J$28/100,0,1) -> 1 | BD34: =IF(BC34=1000000000,"",('All Data'!Q34-'[1]DCDC Ref'!$J$30)/'[1]DCDC Ref'!$J$30*100) -> 137.36264 | BE34: =ABS(BD34) -> 137.36264 | BH34: =IF(BG34<0,10000,BG34) -> 0 | BJ34: =IF(BC34=0,"",('All Data'!Z34-'[1]DCDC Ref'!$J$28*('[1]DCDC Ref'!$J$29/100))/'[1]DCDC Ref'!$J$28*('[1]DCDC Ref'!$J$29/100)*100) -> 27.310345 | BK34: =IF(BJ34<0,10000,BJ34) -> 27.310345 | BQ34: =IFERROR(BE34*$BP$6+BK34*$BP$7,"") -> 686949.74 | BR34: =IF(BQ34="","",RANK(BQ34,BQ$11:BQ$9930,1)+COUNTIF(BQ$11:BQ34,BQ34)-1) -> 31 | BS34: =RANK(BR34,BR$11:BR$9930,1) -> 31 | BT34: =IFERROR(INDEX($O$11:$O$1013,MATCH(ROWS($BS$11:BS34),$BS$11:$BS$1005,0)),"") -> ETQP5M1R0YLC | BU34: =IF(BT34<>"",BT34,"") -> ETQP5M1R0YLC
